Workbook

Sheet Sales_Data_clean
A1: Date | B1: Product | C1: Category | D1: Region | E1: Units Sold | F1: Revenue | G1: Partie 1 )
A2: 45534 | B2: Phone | C2: Electronics | D2: East | E2: 69 | F2: 3588 | G2: The Date column was stored as text and has been converted to proper Excel date values
A3: 45602 | B3: Backpack | C3: Accessories | D3: East | E3: 5 | F3: 420 | G3: now correctly recognized and calculable. Units Sold, Revenue, and category columns
A4: 45418 | B4: Phone | C4: Electronics | D4: West | E4: 62 | F4: 29574 | G4: (Product, Category, Region) were already consistent and correctly formatted.
A5: 45398 | B5: Watch | C5: Fashion | D5: South | E5: 11 | F5: 4400 | G5: There are no duplicates values
A6: 45397 | B6: Printer | C6: Office | D6: East | E6: 70 | F6: 28630
A7: 45433 | B7: Charger | C7: Accessories | D7: North | E7: 18 | F7: 7956
A8: 45474 | B8: Phone | C8: Electronics | D8: West | E8: 69 | F8: 22632
A9: 45587 | B9: Watch | C9: Fashion | D9: North | E9: 21 | F9: 3801
A10: 45325 | B10: Shoes | C10: Fashion | D10: North | E10: 58 | F10: 21576
A11: 45379 | B11: Phone | C11: Electronics | D11: South | E11: 45 | F11: 1260
A12: 45393 | B12: Phone | C12: Electronics | D12: East | E12: 63 | F12: 12159
A13: 45585 | B13: Charger | C13: Accessories | D13: South | E13: 13 | F13: 3315
A14: 45629 | B14: Phone | C14: Electronics | D14: West | E14: 40 | F14: 2760
A15: 45337 | B15: Backpack | C15: Accessories | D15: North | E15: 55 | F15: 16995
A16: 45482 | B16: Laptop | C16: Electronics | D16: North | E16: 39 | F16: 14430
A17: 45407 | B17: Tablet | C17: Electronics | D17: East | E17: 36 | F17: 17172
... A751: 45541 | B751: Printer | C751: Office | D751: East | E751: 44 | F751: 9592

Sheet pivot_tables
A1: 1)Pivot_tables:Column Chart | L1: 2)Pivot_tables:Bar Chart | S1: 4)Pivot_table:Pie Chart
AO2: 11)Pivot table graphiques 11
A3: Row Labels | B3: Sum of Revenue | C3: Cumule of Revenue | AO3: Category | AP3: Amount
A4: janv | B4: 809661 | C4: =SUM($B$4:B4) -> 809661 | L4: Row Labels | M4: Sum of Revenue | S4: Row Labels | T4: Sum of Revenue | AO4: Gross Revenue | AP4: 8242421
A5: févr | B5: 604224 | C5: =SUM($B$4:B5) -> 1413885 | L5: East | M5: 2330543 | S5: Accessories | T5: 2617648 | AO5: Returns | AP5: -150000
A6: mars | B6: 473553 | C6: =SUM($B$4:B6) -> 1887438 | L6: North | M6: 1854020 | S6: Electronics | T6: 2293577 | AE6: Row Labels | AF6: Sum of Revenue | AG6: Sum of Units Sold | AH6: Revenue % | AI6: Units Sold % | AO6: Operating Costs | AP6: -200000
A7: avr | B7: 573481 | C7: =SUM($B$4:B7) -> 2460919 | L7: South | M7: 2096451 | S7: Fashion | T7: 1604305 | AE7: Backpack | AF7: 800058 | AG7: 3016 | AH7: =AF7/MAX($AF$7:$AF$16)*100 -> 81.40209 | AI7: =AG7/MAX($AG$7:$AG$16)*100 -> 87.57259 | AO7: Taxes | AP7: -100000
A8: mai | B8: 905275 | C8: =SUM($B$4:B8) -> 3366194 | L8: West | M8: 1961407 | S8: Office | T8: 1726891 | AE8: Charger | AF8: 956224 | AG8: 3366 | AH8: =AF8/MAX($AF$7:$AF$16)*100 -> 97.291237 | AI8: =AG8/MAX($AG$7:$AG$16)*100 -> 97.735192 | AO8: Net Revenue | AP8: =SUM(AP4,AP5,AP6,AP7) -> 7792421
A9: juin | B9: 808368 | C9: =SUM($B$4:B9) -> 4174562 | L9: Grand Total | M9: 8242421 | S9: Grand Total | T9: 8242421 | AE9: Desk Lamp | AF9: 744044 | AG9: 2836 | AH9: =AF9/MAX($AF$7:$AF$16)*100 -> 75.702932 | AI9: =AG9/MAX($AG$7:$AG$16)*100 -> 82.346109
A10: juil | B10: 802972 | C10: =SUM($B$4:B10) -> 4977534 | AE10: Headphones | AF10: 861366 | AG10: 3093 | AH10: =AF10/MAX($AF$7:$AF$16)*100 -> 87.639887 | AI10: =AG10/MAX($AG$7:$AG$16)*100 -> 89.808362
A11: août | B11: 734280 | C11: =SUM($B$4:B11) -> 5711814 | AE11: Laptop | AF11: 751676 | AG11: 2869 | AH11: =AF11/MAX($AF$7:$AF$16)*100 -> 76.479452 | AI11: =AG11/MAX($AG$7:$AG$16)*100 -> 83.304297
A12: sept | B12: 480196 | C12: =SUM($B$4:B12) -> 6192010 | AE12: Phone | AF12: 910949 | AG12: 3444 | AH12: =AF12/MAX($AF$7:$AF$16)*100 -> 92.684721 | AI12: =AG12/MAX($AG$7:$AG$16)*100 -> 100
A13: oct | B13: 631870 | C13: =SUM($B$4:B13) -> 6823880 | AE13: Printer | AF13: 982847 | AG13: 3361 | AH13: =AF13/MAX($AF$7:$AF$16)*100 -> 100 | AI13: =AG13/MAX($AG$7:$AG$16)*100 -> 97.590012
A14: nov | B14: 726704 | C14: =SUM($B$4:B14) -> 7550584 | R14: Accessories | S14: 2617648 | AE14: Shoes | AF14: 686150 | AG14: 2568 | AH14: =AF14/MAX($AF$7:$AF$16)*100 -> 69.812494 | AI14: =AG14/MAX($AG$7:$AG$16)*100 -> 74.56446
A15: déc | B15: 691837 | C15: =SUM($B$4:B15) -> 8242421 | R15: Electronics | S15: 2293577 | AE15: Tablet | AF15: 630952 | AG15: 2300 | AH15: =AF15/MAX($AF$7:$AF$16)*100 -> 64.19636 | AI15: =AG15/MAX($AG$7:$AG$16)*100 -> 66.782811
A16: Grand Total | B16: 8242421 | R16: Fashion | S16: 1604305 | AE16: Watch | AF16: 918155 | AG16: 3306 | AH16: =AF16/MAX($AF$7:$AF$16)*100 -> 93.417897 | AI16: =AG16/MAX($AG$7:$AG$16)*100 -> 95.993031
L17: Country | M17: Revenue | R17: Office | S17: 1726891 | AE17: Grand Total | AF17: 8242421 | AG17: 30159
L18: United States | M18: 2330543
L19: France | M19: 1854020
L20: Brazil | M20: 2096451
L21: Japan | M21: 1961407
R23: 10) Data for Pareto
R24: Column1 | S24: Column2
R25: Backpack | S25: 800058
R26: Charger | S26: 956224
R27: Desk Lamp | S27: 744044
R28: Headphones | S28: 861366
R29: Laptop | S29: 751676
R30: Phone | S30: 910949
R31: Printer | S31: 982847
R32: Shoes | S32: 686150
R33: Tablet | S33: 630952
R34: Watch | S34: 918155 | AE34: 7)Data for Radar graphiques
AE35: Column1 | AF35: Column2 | AG35: Column3
AE36: Backpack | AF36: 81.40209 | AG36: 87.57259
AE37: Charger | AF37: 97.291237 | AG37: 97.735192
AE38: Desk Lamp | AF38: 75.702932 | AG38: 82.346109
AE39: Headphones | AF39: 87.639887 | AG39: 89.808362
AE40: Laptop | AF40: 76.479452 | AG40: 83.304297
AE41: Phone | AF41: 92.684721 | AG41: 100
...

Sheet graphiques
A3: 1)Column Chart | I3: 2)Bar Chart | Q3: 3) Line Chart | Y3: 4)Pie Chart | AG3: 5) Scatter Chart | AO3: 6) Area Chart | AX3: 7) Radar Chart | BF3: 9) Histogram | BO3: 10)Pareto Chart | BW3: 11)Waterfall Chart | CE3: 12)Box & Whisker Chart | CN3: 13)Treemap Chart | CV3: 14)Map Chart | DE3: 15)Recommended Charts

Sheet Insights
A5: Row Labels | B5: Sum of Revenue | C5: KPI 1 | D5: KPI 2 | E5: kPI3
A6: East | B6: 2330543 | C6: =SUM(Sales_Data_clean!F2:F751) -> 8242421 | D6: =AVERAGEIF(Sales_Data_clean!D2:D752,"East",Sales_Data_clean!F2:F752) -> 12075.352 | E6: =SUM(Sales_Data_clean!E2:E752) -> 30159
A7: Accessories | B7: 742434
A8: janv | B8: 36505
A9: févr | B9: 49191
A10: mars | B10: 32739
A11: avr | B11: 75547 | D11: =AVERAGEIF(Sales_Data_clean!D2:D752,"North",Sales_Data_clean!F2:F752) -> 9507.7949
A12: mai | B12: 60609
A13: juin | B13: 57691
A14: juil | B14: 65921
A15: août | B15: 101761
A16: sept | B16: 35022 | D16: =AVERAGEIF(Sales_Data_clean!D2:D752,"South",Sales_Data_clean!F2:F752) -> 11210.968
A17: oct | B17: 3290
A18: nov | B18: 140241
A19: déc | B19: 83917
A20: Electronics | B20: 563530
A21: Fashion | B21: 494979 | D21: =AVERAGEIF(Sales_Data_clean!D2:D752,"West",Sales_Data_clean!F2:F752) -> 11208.04
A22: Office | B22: 529600
A23: North | B23: 1854020
A24: Accessories | B24: 525356
A25: janv | B25: 70203
A26: févr | B26: 48922
A27: mars | B27: 15610
A28: avr | B28: 13269
A29: mai | B29: 35645
A30: juin | B30: 37987
A31: juil | B31: 34495
A32: août | B32: 74754
A33: sept | B33: 40393
... A74: Grand Total | B74: 8242421

Sheet Dashboard
